Workbook
Name lst_ActiveStatus: LOOKUP!$T$4:$T$5
Name lst_AdmissionStatus: LOOKUP!$J$4:$J$8
Name lst_BedStatus: LOOKUP!$U$4:$U$7
Name lst_BloodGroup: LOOKUP!$B$4:$B$11
Name lst_ClaimStatus: LOOKUP!$L$4:$L$9
Name lst_Department: LOOKUP!$E$4:$E$12
Name lst_Designation: LOOKUP!$F$4:$F$8
Name lst_DiscountType: LOOKUP!$O$4:$O$8
Name lst_DoctorNames: LOOKUP!$V$4:$W$13
Name lst_DoctorStatus: LOOKUP!$R$4:$R$7
Name lst_Gender: LOOKUP!$A$4:$A$6
Name lst_GSTPercent: LOOKUP!$Q$4:$Q$7
Name lst_IDProof: LOOKUP!$C$4:$C$8
Name lst_InsCoverage: LOOKUP!$S$4:$S$6
Name lst_InsuranceProvider: LOOKUP!$P$4:$P$14
Name lst_PayerType: LOOKUP!$D$4:$D$6
Name lst_PaymentMode: LOOKUP!$K$4:$K$10
Name lst_PaymentStatus: LOOKUP!$M$4:$M$8
Name lst_ServiceCategory: LOOKUP!$G$4:$G$11
Name lst_StaffRole: LOOKUP!$N$4:$N$10
Name lst_VisitType: LOOKUP!$I$4:$I$6
Name lst_WardType: LOOKUP!$H$4:$H$8
Name Slicer_Department: #N/A
Name Slicer_Discount_Type: #N/A
Name Slicer_Payment_Status: #N/A
Name Slicer_Status: #N/A
Name Slicer_Visit_Type: #N/A

Sheet INSTRUCTIONS
B2: CityMed Multi-Specialty Hospital
B3: Patient & Billing Management System | Est. 2024 | Version 1.0
B5: NAVIGATE TO MODULE
B6: PT_Master — Patient Register | C6: Register new patients, search existing records, update contact and insurance details | E6: Receptionist
B7: DR_Master — Doctor Directory | C7: Manage doctor profiles, consultation fees, department assignments | E7: Admin
B8: SVC_RateCard — Services & Pricing | C8: Add or update services, procedures, lab tests and their rates | E8: Admin
B9: BED_Master — Bed Management | C9: Track bed availability, ward types, occupancy status | E9: Admin / Nurse
B10: ADM_Log — Admissions & OPD | C10: ADM_Log — Admissions & OPD | E10: Receptionist
B11: SVC_Log — Services Consumed | C11: Log all services, tests, procedures given to admitted patients | E11: Nurse / Lab
B12: BILLING — Invoice Generation | C12: Generate patient bills, apply insurance split, issue final invoices | E12: Billing Clerk
B13: DASHBOARD — KPI & Reports | C13: View live hospital performance metrics, revenue, occupancy, collections | E13: Manager
B15: IMPORTANT INFORMATION
B16: Last Updated: | C16: =TODAY() -> 46169
B17: Version | C17: 1.0 — CityMed HMS (Excel 2021)
B18: Support Contact:
B19: Data Backup:

Sheet DASHBOARD
B2: CityMed Multi-Specialty Hospital — Operations Dashboard
B3: =("Dashboard refreshed: "&TEXT(TODAY(),"DD MMM YYYY")&" | Data is live and auto-updating") -> Dashboard refreshed: 27 May 2026 | Data is live and auto-updating
B4: PATIENT VOLUME
B5: Metric | C5: Value | D5: Metric | E5: Value | F5: Metric | G5: Value
B6: Total Patients | C6: =COUNTA(PT_Master!A5:A5000) -> 200 | D6: OPD Visits | E6: =COUNTIF(ADM_Log!D5:D5000,"OPD") -> 84 | F6: IPD Admissions | G6: =COUNTIF(ADM_Log!D5:D5000,"IPD") -> 55
B7: Active IPD Patients | C7: =COUNTIFS(ADM_Log!D5:D1004,"IPD",ADM_Log!O5:O1004,"Active") -> 6 | D7: Discharged This Month | E7: {=SUMPRODUCT( (ADM_Log!O5:O1004="Discharged")* (MONTH(IFERROR(DATEVALUE(ADM_Log!F5:F1004),0))=MONTH(TODAY()))* (YEAR(IFERROR(DATEVALUE(ADM_Log!F5:F1004),0))=YEAR(TODAY())) )} -> 5 | F7: Emergency Cases | G7: =COUNTIF(ADM_Log!D5:D5000,"Emergency") -> 11
B8: Avg Length of Stay | C8: =IFERROR(AVERAGEIF(ADM_Log!G5:G5000,">"&0,ADM_Log!G5:G5000),0) -> 5.7878788 | D8: New Patients This Month | E8: {=SUMPRODUCT((MONTH(IFERROR(DATEVALUE(PT_Master!B5:B204),0))=MONTH(TODAY()))*(YEAR(IFERROR(DATEVALUE(PT_Master!B5:B204),0))=YEAR(TODAY()))*(PT_Master!B5:B204<>""))} -> 5 | F8: LAMA Cases | G8: =COUNTIF(ADM_Log!O5:O5000,"LAMA") -> 7
B10: REVENUE SUMMARY
B11: Metric | C11: Amount (₹) | D11: Metric | E11: Amount (₹) | F11: Metric | G11: Amount (₹)
B12: Gross Revenue (₹) | C12: =IFERROR(SUM(BILLING!J5:J5000),0) -> 13492580 | D12: Net Revenue (₹) | E12: =IFERROR(SUM(BILLING!M5:M5000),0) -> 13101277 | F12: Total Discounts (₹) | G12: =IFERROR(SUM(BILLING!L5:L5000),0) -> 391302.76
B13: Rev Per Bed Per Day (₹) | C13: =IFERROR(SUM(BILLING!J5:J1004)/SUMIF(ADM_Log!D5:D1004,"IPD",ADM_Log!G5:G1004),0) -> 37067.527 | D13: Avg Bill Value (₹) | E13: =IFERROR(AVERAGE(BILLING!M5:M5000),0) -> 87341.848 | F13: Highest Single Bill (₹) | G13: =IFERROR(MAX(BILLING!J5:J5000),0) -> 472828.5
B14: Services Revenue (₹) | C14: =IFERROR(SUM(BILLING!G5:G5000),0) -> 12222750 | D14: Room Revenue (₹) | E14: =IFERROR(SUM(BILLING!H5:H5000),0) -> 1075500 | F14: Doctor Fee Revenue (₹) | G14: =IFERROR(SUM(BILLING!I5:I5000),0) -> 194330
B16: COLLECTIONS & ACCOUNTS RECEIVABLE
B17: Metric | C17: Amount (₹) | D17: Metric | E17: Amount (₹) | F17: Metric | G17: Amount (₹)
B18: Total Collected (₹) | C18: =IFERROR(PAYMENTS!E4,0) -> 5434705.8 | D18: Total Outstanding (₹) | E18: =IFERROR(PAYMENTS!G4,0) -> 2356305.2 | F18: Collection Rate | G18: =IFERROR(PAYMENTS!I4,"0.0%") -> 69.8%
B19: AR 0-30 Days (₹) | C19: =IFERROR(SUMIF(PAYMENTS!L6:L2005,"0-30 Days",PAYMENTS!J6:J2005),0) -> 162472.68 | D19: AR 31-60 Days (₹) | E19: =IFERROR(SUMIF(PAYMENTS!L6:L2005,"31-60 Days",PAYMENTS!J6:J2005),0) -> 87853.88 | F19: AR 61-90 Days (₹) | G19: =IFERROR(SUMIF(PAYMENTS!L6:L2005,"61-90 Days",PAYMENTS!J6:J2005),0) -> 356654.16
B20: Critical AR 90+ (₹) | C20: =IFERROR(PAYMENTS!K4,0) -> 1749114.5 | D20: Unpaid Bills Count | E20: =COUNTIF(BILLING!P5:P5000,"Unpaid") -> 18 | F20: Partial Payment Bills | G20: =COUNTIF(BILLING!P5:P5000,"Partial") -> 37
B22: BED OCCUPANCY
B23: Metric | C23: Value | D23: Metric | E23: Value | F23: Metric | G23: Value
B24: Total Beds | C24: =BED_Master!C3 -> 115 | D24: Occupied Beds | E24: =BED_Master!G3 -> 12 | F24: Occupancy Rate | G24: =IFERROR(BED_Master!G3/BED_Master!C3,0) -> 0.10434783
B25: Available Beds | C25: =BED_Master!E3 -> 15 | D25: Under Maintenance | E25: =COUNTIF(BED_Master!G5:G119,"Maintenance") -> 0 | F25: Reserved Beds | G25: =COUNTIF(BED_Master!G5:G119,"Reserved") -> 2
B26: ICU Beds Occupied | C26: =COUNTIFS(BED_Master!B5:B119,"ICU",BED_Master!G5:G119,"Occupied") -> 3 | D26: ICU Beds Available | E26: =COUNTIFS(BED_Master!B5:B119,"ICU",BED_Master!G5:G119,"Available") -> 1 | F26: ICU Occupancy Rate | G26: =IFERROR(C26/(C26+E26),0) -> 0.75
B28: INSURANCE PERFORMANCE
B29: Metric | C29: Amount (₹) | D29: Metric | E29: Amount (₹) | F29: Metric | G29: Amount (₹)
B30: Total Claims Submitted | C30: =COUNTA(INSURANCE!A6:A1005) -> 1000 | D30: Total Claimed (₹) | E30: =IFERROR(INSURANCE!C4,0) -> 4217770 | F30: Total Approved (₹) | G30: =IFERROR(INSURANCE!E4,0) -> 1826643.1
B31: Claims Approval Rate | C31: =IFERROR(INSURANCE!I4,"0.0%") -> 43.3% | D31: Rejected Claims | E31: =IFERROR(INSURANCE!K4,0) -> 15 | F31: Total Variance (₹) | G31: =IFERROR(INSURANCE!G4,0) -> 2391030
B32: Pending Claims | C32: =COUNTIF(INSURANCE!L6:L1005,"Pending") -> 0 | D32: Paid Claims | E32: =COUNTIF(INSURANCE!L6:L1005,"Approved") -> 19 | F32: Avg Approval Rate (₹) | G32: =IFERROR(INSURANCE!E4/COUNTIF(INSURANCE!L6:L1005,"Approved"),0) -> 96139.108
B33: CityMed HMS v1.0 | Confidential — For Management Use Only | Do not distribute

Sheet PIVOT_CHARTS
B1: CityMed Multi-Specialty Hospital — Analytics Dashboard
AW3: Count of Admission_ID | AX3: Column Labels
AW4: Row Labels | AX4: Emergency | AY4: IPD | AZ4: OPD | BA4: Grand Total
AW5: Cardiology | AY5: 6 | AZ5: 18 | BA5: 24
AW6: Diagnostics | AY6: 8 | AZ6: 4 | BA6: 12
AW7: Emergency | AY7: 3 | AZ7: 13 | BA7: 16
AW8: General Medicine | AX8: 2 | AY8: 5 | AZ8: 11 | BA8: 18
AW9: Gynaecology | AX9: 2 | AY9: 2 | AZ9: 9 | BA9: 13
AW10: Orthopaedics | AX10: 3 | AY10: 10 | AZ10: 20 | BA10: 33
AW11: Paediatrics | AY11: 4 | AZ11: 9 | BA11: 13
AW12: Grand Total | AX12: 7 | AY12: 38 | AZ12: 84 | BA12: 129
AW15: Row Labels | AX15: Count of Net_Payable (₹) | AY15: Sum of Insurance_Claim (₹)
AW16: Apr 2026 | AX16: 1 | AY16: 0
AW17: Aug 2025 | AX17: 3 | AY17: 8592.11
AW18: Dec 2025 | AX18: 3 | AY18: 74779.42
AW19: Feb 2026 | AX19: 7 | AY19: 184445.92
AW20: Jan 2026 | AX20: 1 | AY20: 0
AW21: Mar 2026 | AX21: 2 | AY21: 0
AW22: Sep 2025 | AX22: 1 | AY22: 0
AW23: Grand Total | AX23: 18 | AY23: 267817.45
AW36: Row Labels | AX36: Count of Net_Payable (₹) | AY36: Sum of Discount_Ammount (₹)
AW37: Insurance Pending | AX37: 4 | AY37: 22228.49
AW38: Paid | AX38: 11 | AY38: 50171.24
AW39: Partial | AX39: 7 | AY39: 60943.71
AW40: Unpaid | AX40: 1 | AY40: 9653.07
AW41: Grand Total | AX41: 23 | AY41: 142996.51
AX47: Row Labels | AY47: Count of Admission_ID | AZ47: Count of Length_of_Stay
AX48: Dr. Meena Pillai | AY48: 9 | AZ48: 9
AX49: Grand Total | AY49: 9 | AZ49: 9

Sheet PT_Master
A2: CityMed Multi-Specialty Hospital — Patient Master Register
A4: Patient_ID | B4: Reg_Date | C4: Full_Name | D4: Date_of_Birth | E4: Age | F4: Gender | G4: Blood_Group | H4: Phone | I4: Emergency_Name | J4: Emergency_Phone | K4: Address | L4: City | M4: ID_Proof_Type | N4: ID_Proof_No | O4: Payer_Type | P4: Insurance_Provider | Q4: Policy_No | R4: Member_ID | S4: Registerd_By
A5: =IF(C5="","",TEXT(ROW(A1),"PT-00000")) -> PT-00001 | B5: 24/03/2026 | C5: Ananya Roy | D5: 24/03/1985 | E5: =IF(D5="","",DATEDIF(D5,TODAY(),"Y")) -> 41 | F5: Female | G5: B- | H5: 9783058538 | I5: Bhavesh Dutta | J5: 9480289677 | K5: 107, VIP Road | L5: 107, VIP Road | M5: Driving Licence | N5: 348581372836 | O5: Insurance | P5: Care Health Insurance | Q5: POL858660 | R5: MEM63751 | S5: Receptionist
A6: =IF(C6="","",TEXT(ROW(A2),"PT-00000")) -> PT-00002 | B6: 31/12/2025 | C6: Rahul Sharma | D6: 21/06/2004 | E6: =IF(D6="","",DATEDIF(D6,TODAY(),"Y")) -> 21 | F6: Male | G6: B+ | H6: 9919062257 | I6: Tarun Patra | J6: 9455221955 | K6: 89, Camac Street | L6: 89, Camac Street | M6: Passport | N6: 665936330304 | O6: Self-Pay | S6: Ward Nurse
A7: =IF(C7="","",TEXT(ROW(A3),"PT-00000")) -> PT-00003 | B7: 02/01/2026 | C7: Priya Mehta | D7: 26/10/2004 | E7: =IF(D7="","",DATEDIF(D7,TODAY(),"Y")) -> 21 | F7: Male | G7: O- | H7: 9800862269 | I7: Rani Dubey | J7: 9347607381 | K7: 61, BT Road | L7: 61, BT Road | M7: PAN Card | N7: 357924695572 | O7: Corporate | S7: Billing Clerk
A8: =IF(C8="","",TEXT(ROW(A4),"PT-00000")) -> PT-00004 | B8: 04/07/2025 | C8: Debasis Mondal | D8: 19/04/1976 | E8: =IF(D8="","",DATEDIF(D8,TODAY(),"Y")) -> 50 | F8: Male | G8: A+ | H8: 9261768743 | I8: Gaurav Verma | J8: 9353065117 | K8: 90, Lake Avenue | L8: 90, Lake Avenue | M8: PAN Card | N8: 437947866314 | O8: Self-Pay | S8: Ward Nurse
A9: =IF(C9="","",TEXT(ROW(A5),"PT-00000")) -> PT-00005 | B9: 05/05/2026 | C9: Sneha Das | D9: 19/03/1972 | E9: =IF(D9="","",DATEDIF(D9,TODAY(),"Y")) -> 54 | F9: Female | G9: B- | H9: 9309852596 | I9: Tanvi Patra | J9: 9289105347 | K9: 132, Elgin Road | L9: 132, Elgin Road | M9: Passport | N9: 509861130823 | O9: Insurance | P9: Bajaj Allianz Health | Q9: POL652928 | R9: MEM23187 | S9: Receptionist
A10: =IF(C10="","",TEXT(ROW(A6),"PT-00000")) -> PT-00006 | B10: 29/09/2025 | C10: Amit Gupta | D10: 06/09/2015 | E10: =IF(D10="","",DATEDIF(D10,TODAY(),"Y")) -> 10 | F10: Male | G10: B+ | H10: 9193188214 | I10: Nisha Nair | J10: 9211988429 | K10: 153, VIP Road | L10: 153, VIP Road | M10: Driving Licence | N10: 91828501402 | O10: Self-Pay | S10: Receptionist
A11: =IF(C11="","",TEXT(ROW(A7),"PT-00000")) -> PT-00007 | B11: 16/04/2026 | C11: Kavita Singh | D11: 28/11/1961 | E11: =IF(D11="","",DATEDIF(D11,TODAY(),"Y")) -> 64 | F11: Male | G11: B- | H11: 9594968614 | I11: Deepak Ganguly | J11: 9436792410 | K11: 70, Ultadanga Main Road | L11: 70, Ultadanga Main Road | M11: Voter ID | N11: 369769232463 | O11: Insurance | P11: MediAssist TPA | Q11: POL869885 | R11: MEM37547 | S11: Billing Clerk
A12: =IF(C12="","",TEXT(ROW(A8),"PT-00000")) -> PT-00008 | B12: 08/06/2025 | C12: Suresh Chatterjee | D12: 22/08/1977 | E12: =IF(D12="","",DATEDIF(D12,TODAY(),"Y")) -> 48 | F12: Female | G12: A+ | H12: 9929816846 | I12: Smita Pandey | J12: 9644264885 | K12: 108, Jessore Road | L12: 108, Jessore Road | M12: PAN Card | N12: 978780650858 | O12: Self-Pay | S12: Ward Nurse
A13: =IF(C13="","",TEXT(ROW(A9),"PT-00000")) -> PT-00009 | B13: 24/09/2025 | C13: Pooja Mukherjee | D13: 06/12/1997 | E13: =IF(D13="","",DATEDIF(D13,TODAY(),"Y")) -> 28 | F13: Male | G13: AB+ | H13: 9172490435 | I13: Sanjay Ghosh | J13: 9127151413 | K13: 87, College Street | L13: 87, College Street | M13: Voter ID | N13: 257679520115 | O13: Corporate | S13: Admin Manager
A14: =IF(C14="","",TEXT(ROW(A10),"PT-00000")) -> PT-00010 | B14: 19/07/2025 | C14: Arjun Bose | D14: 17/03/1995 | E14: =IF(D14="","",DATEDIF(D14,TODAY(),"Y")) -> 31 | F14: Female | G14: A+ | H14: 9970006310 | I14: Poonam Pal | J14: 9226308805 | K14: 82, VIP Road | L14: 82, VIP Road | M14: Driving Licence | N14: 239916194682 | O14: Self-Pay | S14: Billing Clerk
A15: =IF(C15="","",TEXT(ROW(A11),"PT-00000")) -> PT-00011 | B15: 03/08/2025 | C15: Meena Sen | D15: 17/01/2015 | E15: =IF(D15="","",DATEDIF(D15,TODAY(),"Y")) -> 11 | F15: Female | G15: AB- | H15: 9715090376 | I15: Tanvi Ghosh | J15: 9990832605 | K15: 166, Gariahat Road | L15: 166, Gariahat Road | M15: Driving Licence | N15: 449571664588 | O15: Insurance | P15: New India Assurance | Q15: POL661373 | R15: MEM85123 | S15: Billing Clerk
A16: =IF(C16="","",TEXT(ROW(A12),"PT-00000")) -> PT-00012 | B16: 02/01/2026 | C16: Vikram Ghosh | D16: 08/06/1970 | E16: =IF(D16="","",DATEDIF(D16,TODAY(),"Y")) -> 55 | F16: Female | G16: O+ | H16: 9825203461 | I16: Sarla Rathore | J16: 9308177964 | K16: 120, Jessore Road | L16: 120, Jessore Road | M16: Aadhaar | N16: 463468254821 | O16: Self-Pay | S16: Billing Clerk
A17: =IF(C17="","",TEXT(ROW(A13),"PT-00000")) -> PT-00013 | B17: 30/10/2025 | C17: Divya Banerjee | D17: 09/10/1984 | E17: =IF(D17="","",DATEDIF(D17,TODAY(),"Y")) -> 41 | F17: Male | G17: AB- | H17: 9966939462 | I17: Seema Sharma | J17: 9741675685 | K17: 166, Rabindra Sarani | L17: 166, Rabindra Sarani | M17: Aadhaar | N17: 216953194048 | O17: Insurance | P17: Aditya Birla Health | Q17: POL508333 | R17: MEM46946 | S17: Billing Clerk
A18: =IF(C18="","",TEXT(ROW(A14),"PT-00000")) -> PT-00014 | B18: 07/09/2025 | C18: Rajan Dey | D18: 06/07/2015 | E18: =IF(D18="","",DATEDIF(D18,TODAY(),"Y")) -> 10 | F18: Male | G18: AB- | H18: 9233355247 | I18: Divya Desai | J18: 9387700006 | K18: 34, Ultadanga Main Road | L18: 34, Ultadanga Main Road | M18: Driving Licence | N18: 139324261256 | O18: Insurance | P18: ICICI Lombard Health | Q18: POL966282 | R18: MEM44888 | S18: Ward Nurse
A19: =IF(C19="","",TEXT(ROW(A15),"PT-00000")) -> PT-00015 | B19: 08/03/2026 | C19: Sunita Pal | D19: 11/12/1995 | E19: =IF(D19="","",DATEDIF(D19,TODAY(),"Y")) -> 30 | F19: Female | G19: B+ | H19: 9711326792 | I19: Poonam Sen | J19: 9643258518 | K19: 66, Lake Avenue | L19: 66, Lake Avenue | M19: Driving Licence | N19: 268322340916 | O19: Insurance | P19: Star Health Insurance | Q19: POL731832 | R19: MEM46538 | S19: Admin Manager
A20: =IF(C20="","",TEXT(ROW(A16),"PT-00000")) -> PT-00016 | B20: 20/10/2025 | C20: Ajay Nath | D20: 05/08/1957 | E20: =IF(D20="","",DATEDIF(D20,TODAY(),"Y")) -> 68 | F20: Female | G20: AB- | H20: 9827162606 | I20: Mukesh Chowdhury | J20: 9693197599 | K20: 166, Park Street | L20: 166, Park Street | M20: Passport | N20: 267587521884 | O20: Insurance | P20: United India Insurance | Q20: POL583367 | R20: MEM55549 | S20: Billing Clerk
A21: =IF(C21="","",TEXT(ROW(A17),"PT-00000")) -> PT-00017 | B21: 15/11/2025 | C21: Nisha Saha | D21: 15/08/1966 | E21: =IF(D21="","",DATEDIF(D21,TODAY(),"Y")) -> 59 | F21: Male | G21: B+ | H21: 9889387399 | I21: Sunita Bhattacharya | J21: 9152965206 | K21: 73, Camac Street | L21: 73, Camac Street | M21: Aadhaar | N21: 177388358474 | O21: Corporate | S21: Receptionist
A22: =IF(C22="","",TEXT(ROW(A18),"PT-00000")) -> PT-00018 | B22: 04/03/2026 | C22: Sanjay Biswas | D22: 22/04/1998 | E22: =IF(D22="","",DATEDIF(D22,TODAY(),"Y")) -> 28 | F22: Male | G22: O+ | H22: 9796274488 | I22: Shreya Saha | J22: 9453376825 | K22: 11, Station Road | L22: 11, Station Road | M22: Driving Licence | N22: 845520509553 | O22: Self-Pay | S22: Billing Clerk
A23: =IF(C23="","",TEXT(ROW(A19),"PT-00000")) -> PT-00019 | B23: 19/01/2026 | C23: Rekha Chakraborty | D23: 26/05/2014 | E23: =IF(D23="","",DATEDIF(D23,TODAY(),"Y")) -> 12 | F23: Male | G23: B+ | H23: 9207030906 | I23: Tanvi Ganguly | J23: 9785596204 | K23: 68, Rabindra Sarani | L23: 68, Rabindra Sarani | M23: Voter ID | N23: 322507563159 | O23: Corporate | S23: Admin Manager
A24: =IF(C24="","",TEXT(ROW(A20),"PT-00000")) -> PT-00020 | B24: 01/04/2026 | C24: Manish Mitra | D24: 24/01/1975 | E24: =IF(D24="","",DATEDIF(D24,TODAY(),"Y")) -> 51 | F24: Female | G24: AB- | H24: 9317407204 | I24: Nisha Agarwal | J24: 9224635790 | K24: 131, Jessore Road | L24: 131, Jessore Road | M24: Voter ID | N24: 677307814158 | O24: Corporate | S24: Ward Nurse
A25: =IF(C25="","",TEXT(ROW(A21),"PT-00000")) -> PT-00021 | B25: 03/02/2026 | C25: Geeta Paul | D25: 26/06/1959 | E25: =IF(D25="","",DATEDIF(D25,TODAY(),"Y")) -> 66 | F25: Female | G25: O+ | H25: 9790521986 | I25: Vandana Mishra | J25: 9985495542 | K25: 97, VIP Road | L25: 97, VIP Road | M25: Passport | N25: 103862230040 | O25: Corporate | S25: Receptionist
A26: =IF(C26="","",TEXT(ROW(A22),"PT-00000")) -> PT-00022 | B26: 30/09/2025 | C26: Arun Karmakar | D26: 08/03/1976 | E26: =IF(D26="","",DATEDIF(D26,TODAY(),"Y")) -> 50 | F26: Female | G26: A- | H26: 9266624496 | I26: Amit Saha | J26: 9978359493 | K26: 92, MG Road | L26: 92, MG Road | M26: Passport | N26: 821540988679 | O26: Corporate | S26: Billing Clerk
A27: =IF(C27="","",TEXT(ROW(A23),"PT-00000")) -> PT-00023 | B27: 12/08/2025 | C27: Lata Mandal | D27: 22/01/2005 | E27: =IF(D27="","",DATEDIF(D27,TODAY(),"Y")) -> 21 | F27: Female | G27: B- | H27: 9493820247 | I27: Gaurav Mondal | J27: 9255979728 | K27: 54, Netaji Subhas Road | L27: 54, Netaji Subhas Road | M27: Driving Licence | N27: 171130127333 | O27: Insurance | P27: Bajaj Allianz Health | Q27: POL673253 | R27: MEM10398 | S27: Admin Manager
A28: =IF(C28="","",TEXT(ROW(A24),"PT-00000")) -> PT-00024 | B28: 25/03/2026 | C28: Deepak Sarkar | D28: 20/07/2008 | E28: =IF(D28="","",DATEDIF(D28,TODAY(),"Y")) -> 17 | F28: Female | G28: AB+ | H28: 9660715421 | I28: Poonam Jain | J28: 9980908699 | K28: 162, Ultadanga Main Road | L28: 162, Ultadanga Main Road | M28: PAN Card | N28: 353270246366 | O28: Self-Pay | S28: Billing Clerk
A29: =IF(C29="","",TEXT(ROW(A25),"PT-00000")) -> PT-00025 | B29: 20/03/2026 | C29: Shilpa Patra | D29: 15/07/1979 | E29: =IF(D29="","",DATEDIF(D29,TODAY(),"Y")) -> 46 | F29: Female | G29: B+ | H29: 9449972189 | I29: Ajay Menon | J29: 9815775202 | K29: 93, MG Road | L29: 93, MG Road | M29: Voter ID | N29: 193282719967 | O29: Insurance | P29: HDFC ERGO Health | Q29: POL862973 | R29: MEM45401 | S29: Admin Manager
A30: =IF(C30="","",TEXT(ROW(A26),"PT-00000")) -> PT-00026 | B30: 13/11/2025 | C30: Rajesh Haldar | D30: 16/08/2002 | E30: =IF(D30="","",DATEDIF(D30,TODAY(),"Y")) -> 23 | F30: Female | G30: B- | H30: 9285770693 | I30: Smita Nair | J30: 9948881207 | K30: 106, Park Street | L30: 106, Park Street | M30: Voter ID | N30: 850429433996 | O30: Corporate | S30: Admin Manager
A31: =IF(C31="","",TEXT(ROW(A27),"PT-00000")) -> PT-00027 | B31: 15/07/2025 | C31: Asha Majumdar | D31: 23/09/1977 | E31: =IF(D31="","",DATEDIF(D31,TODAY(),"Y")) -> 48 | F31: Female | G31: O- | H31: 9117631103 | I31: Manjula Banerjee | J31: 9904160644 | K31: 122, Lake Avenue | L31: 122, Lake Avenue | M31: Passport | N31: 768127864485 | O31: Self-Pay | S31: Receptionist
A32: =IF(C32="","",TEXT(ROW(A28),"PT-00000")) -> PT-00028 | B32: 04/03/2026 | C32: Vivek Bhattacharya | D32: 03/04/1964 | E32: =IF(D32="","",DATEDIF(D32,TODAY(),"Y")) -> 62 | F32: Female | G32: B- | H32: 9962422558 | I32: Kartik Tiwari | J32: 9275854686 | K32: 41, MG Road | L32: 41, MG Road | M32: Voter ID | N32: 285455727367 | O32: Insurance | P32: Aditya Birla Health | Q32: POL133628 | R32: MEM87621 | S32: Receptionist
A33: =IF(C33="","",TEXT(ROW(A29),"PT-00000")) -> PT-00029 | B33: 23/06/2025 | C33: Smita Chowdhury | D33: 25/12/1987 | E33: =IF(D33="","",DATEDIF(D33,TODAY(),"Y")) -> 38 | F33: Female | G33: O+ | H33: 9280392878 | I33: Sarla Dey | J33: 9148773878 | K33: 28, Diamond Harbour Road | L33: 28, Diamond Harbour Road | M33: PAN Card | N33: 121150183998 | O33: Self-Pay | S33: Admin Manager
A34: =IF(C34="","",TEXT(ROW(A30),"PT-00000")) -> PT-00030 | B34: 06/06/2025 | C34: Prakash Lahiri | D34: 07/08/1967 | E34: =IF(D34="","",DATEDIF(D34,TODAY(),"Y")) -> 58 | F34: Male | G34: A- | H34: 9963585493 | I34: Indira Bhatt | J34: 9995601154 | K34: 179, Camac Street | L34: 179, Camac Street | M34: Passport | N34: 568372141239 | O34: Insurance | P34: United India Insurance | Q34: POL506231 | R34: MEM46730 | S34: Ward Nurse
A35: =IF(C35="","",TEXT(ROW(A31),"PT-00000")) -> PT-00031 | B35: 05/10/2025 | C35: Usha Ganguly | D35: 28/09/2014 | E35: =IF(D35="","",DATEDIF(D35,TODAY(),"Y")) -> 11 | F35: Male | G35: O- | H35: 9909063790 | I35: Vivek Mukherjee | J35: 9513689640 | K35: 172, Ultadanga Main Road | L35: 172, Ultadanga Main Road | M35: PAN Card | N35: 304199375630 | O35: Self-Pay | S35: Receptionist
A36: =IF(C36="","",TEXT(ROW(A32),"PT-00000")) -> PT-00032 | B36: 08/11/2025 | C36: Nikhil Dutta | D36: 24/04/1972 | E36: =IF(D36="","",DATEDIF(D36,TODAY(),"Y")) -> 54 | F36: Male | G36: A+ | H36: 9716664469 | I36: Prakash Gupta | J36: 9673811373 | K36: 62, BT Road | L36: 62, BT Road | M36: Voter ID | N36: 828508076566 | O36: Self-Pay | S36: Receptionist
A37: =IF(C37="","",TEXT(ROW(A33),"PT-00000")) -> PT-00033 | B37: 09/05/2026 | C37: Anjali Sanyal | D37: 11/03/1960 | E37: =IF(D37="","",DATEDIF(D37,TODAY(),"Y")) -> 66 | F37: Male | G37: O- | H37: 9633972714 | I37: Prakash Sharma | J37: 9508529756 | K37: 163, Station Road | L37: 163, Station Road | M37: Voter ID | N37: 520625913342 | O37: Insurance | P37: MediAssist TPA | Q37: POL376832 | R37: MEM27150 | S37: Ward Nurse
A38: =IF(C38="","",TEXT(ROW(A34),"PT-00000")) -> PT-00034 | B38: 08/12/2025 | C38: Sunil Bhatt | D38: 16/01/2001 | E38: =IF(D38="","",DATEDIF(D38,TODAY(),"Y")) -> 25 | F38: Female | G38: O- | H38: 9757320202 | I38: Kavita Roy | J38: 9399466325 | K38: 11, BT Road | L38: 11, BT Road | M38: Aadhaar | N38: 383938729801 | O38: Self-Pay | S38: Receptionist
A39: =IF(C39="","",TEXT(ROW(A35),"PT-00000")) -> PT-00035 | B39: 27/06/2025 | C39: Poonam Joshi | D39: 16/02/1956 | E39: =IF(D39="","",DATEDIF(D39,TODAY(),"Y")) -> 70 | F39: Female | G39: O+ | H39: 9963736709 | I39: Pallavi Pillai | J39: 9757148892 | K39: 16, Camac Street | L39: 16, Camac Street | M39: Aadhaar | N39: 813961015110 | O39: Corporate | S39: Admin Manager
A40: =IF(C40="","",TEXT(ROW(A36),"PT-00000")) -> PT-00036 | B40: 05/05/2026 | C40: Hemant Patel | D40: 03/11/1971 | E40: =IF(D40="","",DATEDIF(D40,TODAY(),"Y")) -> 54 | F40: Female | G40: A+ | H40: 9615235811 | I40: Manoj Lahiri | J40: 9217766587 | K40: 98, Rabindra Sarani | L40: 98, Rabindra Sarani | M40: PAN Card | N40: 362792330484 | O40: Self-Pay | S40: Admin Manager
A41: =IF(C41="","",TEXT(ROW(A37),"PT-00000")) -> PT-00037 | B41: 14/01/2026 | C41: Madhuri Shah | D41: 28/01/2001 | E41: =IF(D41="","",DATEDIF(D41,TODAY(),"Y")) -> 25 | F41: Female | G41: A+ | H41: 9114475614 | I41: Madhuri Kapoor | J41: 9448077890 | K41: 34, Netaji Subhas Road | L41: 34, Netaji Subhas Road | M41: Voter ID | N41: 24839643733 | O41: Insurance | P41: Star Health Insurance | Q41: POL691456 | R41: MEM89235 | S41: Admin Manager
A42: =IF(C42="","",TEXT(ROW(A38),"PT-00000")) -> PT-00038 | B42: 03/06/2025 | C42: Girish Desai | D42: 02/11/2002 | E42: =IF(D42="","",DATEDIF(D42,TODAY(),"Y")) -> 23 | F42: Female | G42: A+ | H42: 9831452863 | I42: Ananya Agarwal | J42: 9565654407 | K42: 62, Station Road | L42: 62, Station Road | M42: Voter ID | N42: 976407029997 | O42: Self-Pay | S42: Ward Nurse
...

Sheet DR_Master
A2: CityMed Multi-Specialty Hospital — Doctor Directory
A4: Doctor_ID | B4: Full_Name | C4: Designation | D4: Department | E4: Specialization | F4: Qualification | G4: OPD_Fee (₹) | H4: IPD_Daily_Fee (₹) | I4: Emergency_Fee (₹) | J4: Available_Days | K4: OPD_Timing | L4: Status
A5: =IF(B5="","","DR-"&TEXT(ROW(A1),"000")) -> DR-001 | B5: Dr. Arjun Bose | C5: Senior Consultant | D5: Cardiology | E5: Interventional Cardiology | F5: MBBS, MD, DM | G5: 800 | H5: 500 | I5: 1200 | J5: Mon-Sat | K5: 9AM-1PM | L5: Active
A6: =IF(B6="","","DR-"&TEXT(ROW(A2),"000")) -> DR-002 | B6: Dr. Meena Pillai | C6: Head of Department | D6: Gynaecology | E6: Maternal & Fetal Medicine | F6: MBBS, MS | G6: 700 | H6: 450 | I6: 1000 | J6: Mon-Fri | K6: 10AM-2PM | L6: Active
A7: =IF(B7="","","DR-"&TEXT(ROW(A3),"000")) -> DR-003 | B7: Dr. Sanjay Ghosh | C7: Consultant | D7: General Medicine | E7: Internal Medicine | F7: MBBS, MD | G7: 500 | H7: 350 | I7: 800 | J7: Mon-Sat | K7: 8AM-12PM | L7: Active
A8: =IF(B8="","","DR-"&TEXT(ROW(A4),"000")) -> DR-004 | B8: Dr. Ritika Sharma | C8: Senior Consultant | D8: Paediatrics | E8: Neonatology | F8: MBBS, MD | G8: 600 | H8: 400 | I8: 900 | J8: Mon-Fri | K8: 9AM-1PM | L8: Active
A9: =IF(B9="","","DR-"&TEXT(ROW(A5),"000")) -> DR-005 | B9: Dr. Tanmoy Das | C9: Consultant | D9: Orthopaedics | E9: Joint Replacement | F9: MBBS, MS | G9: 650 | H9: 420 | I9: 950 | J9: Tue-Sat | K9: 11AM-3PM | L9: Active
A10: =IF(B10="","","DR-"&TEXT(ROW(A6),"000")) -> DR-006 | B10: Dr. Farhan Qureshi | C10: Resident Doctor | D10: Emergency | E10: Emergency Medicine | F10: MBBS | G10: 300 | H10: 200 | I10: 500 | J10: On-Call | K10: 24x7 | L10: Active
A11: =IF(B11="","","DR-"&TEXT(ROW(A7),"000")) -> DR-007 | B11: Dr. Lipika Sen | C11: Consultant | D11: Diagnostics | E11: Radiology & Imaging | F11: MBBS, MD | G11: 400 | H11: 0 | I11: 600 | J11: Mon-Fri | K11: 9AM-5PM | L11: Active
A12: =IF(B12="","","DR-"&TEXT(ROW(A8),"000")) -> DR-008 | B12: Dr. Prabal Roy | C12: Senior Consultant | D12: General Medicine | E12: Diabetology | F12: MBBS, MD | G12: 550 | H12: 380 | I12: 850 | J12: Mon-Sat | K12: 8AM-11AM | L12: On Leave
A13: =IF(B13="","","DR-"&TEXT(ROW(A9),"000")) -> DR-009 | B13: Dr. Kamala Nair | C13: Visiting Consultant | D13: Cardiology | E13: Cardiac Surgery | F13: MBBS, MS, MCh | G13: 1200 | H13: 800 | I13: 2000 | J13: Wed & Fri | K13: 2PM-5PM | L13: Active
A14: =IF(B14="","","DR-"&TEXT(ROW(A10),"000")) -> DR-010 | B14: Dr. Subhash Patra | C14: Head of Department | D14: Orthopaedics | E14: Spine Surgery | F14: MBBS, MS | G14: 750 | H14: 500 | I14: 1100 | J14: Mon-Fri | K14: 10AM-1PM | L14: Active
A15: =IF(B15="","","DR-"&TEXT(ROW(A11),"000"))
A16: =IF(B16="","","DR-"&TEXT(ROW(A12),"000"))
A17: =IF(B17="","","DR-"&TEXT(ROW(A13),"000"))
A18: =IF(B18="","","DR-"&TEXT(ROW(A14),"000"))
A19: =IF(B19="","","DR-"&TEXT(ROW(A15),"000"))
A20: =IF(B20="","","DR-"&TEXT(ROW(A16),"000"))
A21: =IF(B21="","","DR-"&TEXT(ROW(A17),"000"))
A22: =IF(B22="","","DR-"&TEXT(ROW(A18),"000"))
A23: =IF(B23="","","DR-"&TEXT(ROW(A19),"000"))
A24: =IF(B24="","","DR-"&TEXT(ROW(A20),"000"))
A25: =IF(B25="","","DR-"&TEXT(ROW(A21),"000"))
A26: =IF(B26="","","DR-"&TEXT(ROW(A22),"000"))
... A104: =IF(B104="","","DR-"&TEXT(ROW(A100),"000"))

Sheet SVC_RateCard
A2: CityMed Multi-Specialty Hospital — Services & Rate Card
A4: Service_Code | B4: Service_Nmae | C4: Category | D4: Department | E4: Unit | F4: Base_Rate (₹) | G4: GST_% | H4: GST_Amount (₹) | I4: Total_Rate (₹) | J4: Insurance_Coverd | K4: Status
A5: =IF(B5="","","SVC-"&TEXT(ROW(A1),"0000")) -> SVC-0001 | B5: General Consultation | C5: Consultation | D5: General Medicine | E5: Per Visit | F5: 500 | G5: 0 | H5: =IF(F5="","",F5*G5/100) -> 0 | I5: =IF(F5="","",F5+H5) -> 500 | J5: Yes | K5: Active
A6: =IF(B6="","","SVC-"&TEXT(ROW(A2),"0000")) -> SVC-0002 | B6: Cardiology Consultation | C6: Consultation | D6: Cardiology | E6: Per Visit | F6: 800 | G6: 0 | H6: =IF(F6="","",F6*G6/100) -> 0 | I6: =IF(F6="","",F6+H6) -> 800 | J6: Yes | K6: Active
A7: =IF(B7="","","SVC-"&TEXT(ROW(A3),"0000")) -> SVC-0003 | B7: Paediatrics Consultation | C7: Consultation | D7: Paediatrics | E7: Per Visit | F7: 600 | G7: 0 | H7: =IF(F7="","",F7*G7/100) -> 0 | I7: =IF(F7="","",F7+H7) -> 600 | J7: Yes | K7: Active
A8: =IF(B8="","","SVC-"&TEXT(ROW(A4),"0000")) -> SVC-0004 | B8: Orthopaedics Consultation | C8: Consultation | D8: Orthopaedics | E8: Per Visit | F8: 650 | G8: 0 | H8: =IF(F8="","",F8*G8/100) -> 0 | I8: =IF(F8="","",F8+H8) -> 650 | J8: Yes | K8: Active
A9: =IF(B9="","","SVC-"&TEXT(ROW(A5),"0000")) -> SVC-0005 | B9: Gynaecology Consultation | C9: Consultation | D9: Gynaecology | E9: Per Visit | F9: 700 | G9: 0 | H9: =IF(F9="","",F9*G9/100) -> 0 | I9: =IF(F9="","",F9+H9) -> 700 | J9: Yes | K9: Active
A10: =IF(B10="","","SVC-"&TEXT(ROW(A6),"0000")) -> SVC-0006 | B10: Emergency Consultation | C10: Emergency | D10: Emergency | E10: Per Visit | F10: 1200 | G10: 0 | H10: =IF(F10="","",F10*G10/100) -> 0 | I10: =IF(F10="","",F10+H10) -> 1200 | J10: Yes | K10: Active
A11: =IF(B11="","","SVC-"&TEXT(ROW(A7),"0000")) -> SVC-0007 | B11: Complete Blood Count (CBC) | C11: Laboratory | D11: Diagnostics | E11: Per Test | F11: 350 | G11: 5 | H11: =IF(F11="","",F11*G11/100) -> 17.5 | I11: =IF(F11="","",F11+H11) -> 367.5 | J11: Yes | K11: Active
A12: =IF(B12="","","SVC-"&TEXT(ROW(A8),"0000")) -> SVC-0008 | B12: Blood Glucose - Fasting | C12: Laboratory | D12: Diagnostics | E12: Per Test | F12: 120 | G12: 5 | H12: =IF(F12="","",F12*G12/100) -> 6 | I12: =IF(F12="","",F12+H12) -> 126 | J12: Yes | K12: Active
A13: =IF(B13="","","SVC-"&TEXT(ROW(A9),"0000")) -> SVC-0009 | B13: HbA1c Test | C13: Laboratory | D13: Diagnostics | E13: Per Test | F13: 380 | G13: 5 | H13: =IF(F13="","",F13*G13/100) -> 19 | I13: =IF(F13="","",F13+H13) -> 399 | J13: Yes | K13: Active
A14: =IF(B14="","","SVC-"&TEXT(ROW(A10),"0000")) -> SVC-0010 | B14: Lipid Profile | C14: Laboratory | D14: Diagnostics | E14: Per Test | F14: 450 | G14: 5 | H14: =IF(F14="","",F14*G14/100) -> 22.5 | I14: =IF(F14="","",F14+H14) -> 472.5 | J14: Yes | K14: Active
A15: =IF(B15="","","SVC-"&TEXT(ROW(A11),"0000")) -> SVC-0011 | B15: Liver Function Test | C15: Laboratory | D15: Diagnostics | E15: Per Test | F15: 520 | G15: 5 | H15: =IF(F15="","",F15*G15/100) -> 26 | I15: =IF(F15="","",F15+H15) -> 546 | J15: Yes | K15: Active
A16: =IF(B16="","","SVC-"&TEXT(ROW(A12),"0000")) -> SVC-0012 | B16: Kidney Function Test | C16: Laboratory | D16: Diagnostics | E16: Per Test | F16: 480 | G16: 5 | H16: =IF(F16="","",F16*G16/100) -> 24 | I16: =IF(F16="","",F16+H16) -> 504 | J16: Yes | K16: Active
... A54: =IF(B54="","","SVC-"&TEXT(ROW(A50),"0000")) -> SVC-0050 | B54: Endoscopy (Upper GI) | C54: Procedure | D54: General Medicine | E54: Per Procedure | F54: 3500 | G54: 5 | H54: =IF(F54="","",F54*G54/100) -> 175 | I54: =IF(F54="","",F54+H54) -> 3675 | J54: Partial | K54: Active
A55: =IF(B55="","","SVC-"&TEXT(ROW(A51),"0000")) | H55: =IF(F55="","",F55*G55/100) | I55: =IF(F55="","",F55+H55)
A56: =IF(B56="","","SVC-"&TEXT(ROW(A52),"0000")) | H56: =IF(F56="","",F56*G56/100) | I56: =IF(F56="","",F56+H56)
A57: =IF(B57="","","SVC-"&TEXT(ROW(A53),"0000")) | H57: =IF(F57="","",F57*G57/100) | I57: =IF(F57="","",F57+H57)
A58: =IF(B58="","","SVC-"&TEXT(ROW(A54),"0000")) | H58: =IF(F58="","",F58*G58/100) | I58: =IF(F58="","",F58+H58)
A59: =IF(B59="","","SVC-"&TEXT(ROW(A55),"0000")) | H59: =IF(F59="","",F59*G59/100) | I59: =IF(F59="","",F59+H59)
A60: =IF(B60="","","SVC-"&TEXT(ROW(A56),"0000")) | H60: =IF(F60="","",F60*G60/100) | I60: =IF(F60="","",F60+H60)
A61: =IF(B61="","","SVC-"&TEXT(ROW(A57),"0000")) | H61: =IF(F61="","",F61*G61/100) | I61: =IF(F61="","",F61+H61)
A62: =IF(B62="","","SVC-"&TEXT(ROW(A58),"0000")) | H62: =IF(F62="","",F62*G62/100) | I62: =IF(F62="","",F62+H62)
A63: =IF(B63="","","SVC-"&TEXT(ROW(A59),"0000")) | H63: =IF(F63="","",F63*G63/100) | I63: =IF(F63="","",F63+H63)
A64: =IF(B64="","","SVC-"&TEXT(ROW(A60),"0000")) | H64: =IF(F64="","",F64*G64/100) | I64: =IF(F64="","",F64+H64)
A65: =IF(B65="","","SVC-"&TEXT(ROW(A61),"0000")) | H65: =IF(F65="","",F65*G65/100) | I65: =IF(F65="","",F65+H65)
A66: =IF(B66="","","SVC-"&TEXT(ROW(A62),"0000")) | H66: =IF(F66="","",F66*G66/100) | I66: =IF(F66="","",F66+H66)
... A304: =IF(B304="","","SVC-"&TEXT(ROW(A300),"0000")) | H304: =IF(F304="","",F304*G304/100) | I304: =IF(F304="","",F304+H304)

Sheet BED_Master
A2: CityMed Multi-Specialty Hospital — Bed Inventory & Occupancy | B2: Column1 | C2: Column2 | D2: Column3 | E2: Column4 | F2: Column5 | G2: Column6 | H2: Column7 | I2: Column8 | J2: Column9
B3: Total Beds: | C3: =COUNTA(A5:A119) -> 115 | D3: Available: | E3: =COUNTIF(G5:G119,"Available") -> 15 | F3: Occupied: | G3: =COUNTIF(G5:G119,"Occupied") -> 12 | H3: Occupancy_Rate: | I3: =IF(C3=0,"",TEXT(G3/C3,"0%")) -> 10%
A4: Bed_ID | B4: Ward_Type | C4: Room_No | D4: Floor | E4: Department | F4: Daily_Rate (₹) | G4: Status | H4: Current_Patient_ID | I4: Patient_Name | J4: Admission_ID
A5: =IF(B5="","","BED-"&TEXT(ROW(A1),"000")) -> BED-001 | B5: General Ward | C5: G-101 | D5: 1 | E5: General Medicine | F5: 800 | G5: Available
A6: =IF(B6="","","BED-"&TEXT(ROW(A2),"000")) -> BED-002 | B6: General Ward | C6: G-102 | D6: 1 | E6: General Medicine | F6: 800 | G6: Occupied
A7: =IF(B7="","","BED-"&TEXT(ROW(A3),"000")) -> BED-003 | B7: General Ward | C7: G-103 | D7: 1 | E7: General Medicine | F7: 800 | G7: Available
A8: =IF(B8="","","BED-"&TEXT(ROW(A4),"000")) -> BED-004 | B8: General Ward | C8: G-104 | D8: 1 | E8: General Medicine | F8: 800 | G8: Occupied
A9: =IF(B9="","","BED-"&TEXT(ROW(A5),"000")) -> BED-005 | B9: General Ward | C9: G-105 | D9: 1 | E9: General Medicine | F9: 800 | G9: Available
A10: =IF(B10="","","BED-"&TEXT(ROW(A6),"000")) -> BED-006 | B10: General Ward | C10: G-106 | D10: 1 | E10: Paediatrics | F10: 800 | G10: Occupied
A11: =IF(B11="","","BED-"&TEXT(ROW(A7),"000")) -> BED-007 | B11: General Ward | C11: G-107 | D11: 1 | E11: Paediatrics | F11: 800 | G11: Available
A12: =IF(B12="","","BED-"&TEXT(ROW(A8),"000")) -> BED-008 | B12: General Ward | C12: G-108 | D12: 1 | E12: Paediatrics | F12: 800 | G12: Available
A13: =IF(B13="","","BED-"&TEXT(ROW(A9),"000")) -> BED-009 | B13: Semi-Private | C13: S-201 | D13: 2 | E13: General Medicine | F13: 1800 | G13: Occupied
A14: =IF(B14="","","BED-"&TEXT(ROW(A10),"000")) -> BED-010 | B14: Semi-Private | C14: S-202 | D14: 2 | E14: Cardiology | F14: 1800 | G14: Available
A15: =IF(B15="","","BED-"&TEXT(ROW(A11),"000")) -> BED-011 | B15: Semi-Private | C15: S-203 | D15: 2 | E15: Cardiology | F15: 1800 | G15: Occupied
A16: =IF(B16="","","BED-"&TEXT(ROW(A12),"000")) -> BED-012 | B16: Semi-Private | C16: S-204 | D16: 2 | E16: Orthopaedics | F16: 1800 | G16: Available
... A34: =IF(B34="","","BED-"&TEXT(ROW(A30),"000")) -> BED-030 | B34: Emergency | C34: EM-03 | D34: 1 | E34: Emergency | F34: 2000 | G34: Available
A35: =IF(B35="","","BED-"&TEXT(ROW(A31),"000"))
A36: =IF(B36="","","BED-"&TEXT(ROW(A32),"000"))
A37: =IF(B37="","","BED-"&TEXT(ROW(A33),"000"))
A38: =IF(B38="","","BED-"&TEXT(ROW(A34),"000"))
A39: =IF(B39="","","BED-"&TEXT(ROW(A35),"000"))
A40: =IF(B40="","","BED-"&TEXT(ROW(A36),"000"))
A41: =IF(B41="","","BED-"&TEXT(ROW(A37),"000"))
A42: =IF(B42="","","BED-"&TEXT(ROW(A38),"000"))
A43: =IF(B43="","","BED-"&TEXT(ROW(A39),"000"))
A44: =IF(B44="","","BED-"&TEXT(ROW(A40),"000"))
A45: =IF(B45="","","BED-"&TEXT(ROW(A41),"000"))
A46: =IF(B46="","","BED-"&TEXT(ROW(A42),"000"))
... A120: =IF(B120="","","BED-"&TEXT(ROW(A116),"000"))

Sheet ADM_Log
A2: CityMed Multi-Specialty Hospital — Admissions & OPD Log
A4: Admission_ID | B4: Patient_ID | C4: Patient_Name | D4: Visit_Type | E4: Admission_Date | F4: Discharge_Date | G4: Length_of_Stay | H4: Department | I4: Doctor_ID | J4: Doctor_Name | K4: Bed_ID | L4: Ward_Type | M4: Primary_Diagnosis | N4: ICD10_Code | O4: Status | P4: Referred_By | Q4: Enterd_By
A5: =IF(B5="","","ADM-"&TEXT(ROW(A1),"00000")) -> ADM-00001 | B5: PT-00001 | C5: =IF(B5="","",IFERROR(_xlfn.XLOOKUP(B5,PT_Master!A:A,PT_Master!C:C),"Patient ID not found")) -> Ananya Roy | D5: OPD | E5: 02/03/2026 | F5: 02/03/2026 | G5: =IF(OR(E5="",F5=""),"",MAX(0,DATEDIF(E5,F5,"D"))) -> 0 | H5: General Medicine | I5: DR-008 | J5: =IF(I5="","",IFERROR(_xlfn.XLOOKUP(I5,DR_Master!A:A,DR_Master!B:B),"Doctor ID not found")) -> Dr. Prabal Roy | L5: =IF(K5="","",IFERROR(_xlfn.XLOOKUP(K5,BED_Master!A:A,BED_Master!B:B),"Bed ID not found")) | M5: Atrial Fibrillation | N5: I48.9 | O5: Discharged | P5: Self | Q5: Billing Clerk
A6: =IF(B6="","","ADM-"&TEXT(ROW(A2),"00000")) -> ADM-00002 | B6: PT-00002 | C6: =IF(B6="","",IFERROR(_xlfn.XLOOKUP(B6,PT_Master!A:A,PT_Master!C:C),"Patient ID not found")) -> Rahul Sharma | D6: OPD | E6: 19/08/2025 | F6: 19/08/2025 | G6: =IF(OR(E6="",F6=""),"",MAX(0,DATEDIF(E6,F6,"D"))) -> 0 | H6: Orthopaedics | I6: DR-005 | J6: =IF(I6="","",IFERROR(_xlfn.XLOOKUP(I6,DR_Master!A:A,DR_Master!B:B),"Doctor ID not found")) -> Dr. Tanmoy Das | L6: =IF(K6="","",IFERROR(_xlfn.XLOOKUP(K6,BED_Master!A:A,BED_Master!B:B),"Bed ID not found")) | M6: Lumbar Disc Herniation | N6: M51.1 | O6: Discharged | P6: Online Booking | Q6: Receptionist
A7: =IF(B7="","","ADM-"&TEXT(ROW(A3),"00000")) -> ADM-00003 | B7: PT-00003 | C7: =IF(B7="","",IFERROR(_xlfn.XLOOKUP(B7,PT_Master!A:A,PT_Master!C:C),"Patient ID not found")) -> Priya Mehta | D7: OPD | E7: 11/03/2026 | F7: 11/03/2026 | G7: =IF(OR(E7="",F7=""),"",MAX(0,DATEDIF(E7,F7,"D"))) -> 0 | H7: General Medicine | I7: DR-003 | J7: =IF(I7="","",IFERROR(_xlfn.XLOOKUP(I7,DR_Master!A:A,DR_Master!B:B),"Doctor ID not found")) -> Dr. Sanjay Ghosh | L7: =IF(K7="","",IFERROR(_xlfn.XLOOKUP(K7,BED_Master!A:A,BED_Master!B:B),"Bed ID not found")) | M7: Paediatric Bronchitis | N7: J20.9 | O7: Discharged | P7: Specialist Referral | Q7: Admin Manager
A8: =IF(B8="","","ADM-"&TEXT(ROW(A4),"00000")) -> ADM-00004 | B8: PT-00004 | C8: =IF(B8="","",IFERROR(_xlfn.XLOOKUP(B8,PT_Master!A:A,PT_Master!C:C),"Patient ID not found")) -> Debasis Mondal | D8: Emergency | E8: 27/03/2026 | F8: 29/03/2026 | G8: =IF(OR(E8="",F8=""),"",MAX(0,DATEDIF(E8,F8,"D"))) -> 2 | H8: Orthopaedics | I8: DR-010 | J8: =IF(I8="","",IFERROR(_xlfn.XLOOKUP(I8,DR_Master!A:A,DR_Master!B:B),"Doctor ID not found")) -> Dr. Subhash Patra | L8: =IF(K8="","",IFERROR(_xlfn.XLOOKUP(K8,BED_Master!A:A,BED_Master!B:B),"Bed ID not found")) | M8: Neonatal Jaundice | N8: P59.9 | O8: Discharged | P8: Self | Q8: Receptionist
A9: =IF(B9="","","ADM-"&TEXT(ROW(A5),"00000")) -> ADM-00005 | B9: PT-00005 | C9: =IF(B9="","",IFERROR(_xlfn.XLOOKUP(B9,PT_Master!A:A,PT_Master!C:C),"Patient ID not found")) -> Sneha Das | D9: IPD | E9: 04/10/2025 | F9: 15/10/2025 | G9: =IF(OR(E9="",F9=""),"",MAX(0,DATEDIF(E9,F9,"D"))) -> 11 | H9: General Medicine | I9: DR-008 | J9: =IF(I9="","",IFERROR(_xlfn.XLOOKUP(I9,DR_Master!A:A,DR_Master!B:B),"Doctor ID not found")) -> Dr. Prabal Roy | K9: BED-007 | L9: =IF(K9="","",IFERROR(_xlfn.XLOOKUP(K9,BED_Master!A:A,BED_Master!B:B),"Bed ID not found")) -> General Ward | M9: Hypertension | N9: I10 | O9: Discharged | P9: Self | Q9: Ward Nurse
A10: =IF(B10="","","ADM-"&TEXT(ROW(A6),"00000")) -> ADM-00006 | B10: PT-00006 | C10: =IF(B10="","",IFERROR(_xlfn.XLOOKUP(B10,PT_Master!A:A,PT_Master!C:C),"Patient ID not found")) -> Amit Gupta | D10: OPD | E10: 22/01/2026 | F10: 22/01/2026 | G10: =IF(OR(E10="",F10=""),"",MAX(0,DATEDIF(E10,F10,"D"))) -> 0 | H10: Cardiology | I10: DR-009 | J10: =IF(I10="","",IFERROR(_xlfn.XLOOKUP(I10,DR_Master!A:A,DR_Master!B:B),"Doctor ID not found")) -> Dr. Kamala Nair | L10: =IF(K10="","",IFERROR(_xlfn.XLOOKUP(K10,BED_Master!A:A,BED_Master!B:B),"Bed ID not found")) | M10: Lumbar Disc Herniation | N10: M51.1 | O10: Discharged | P10: Emergency | Q10: Billing Clerk
A11: =IF(B11="","","ADM-"&TEXT(ROW(A7),"00000")) -> ADM-00007 | B11: PT-00007 | C11: =IF(B11="","",IFERROR(_xlfn.XLOOKUP(B11,PT_Master!A:A,PT_Master!C:C),"Patient ID not found")) -> Kavita Singh | D11: IPD | E11: 17/01/2026 | F11: 25/01/2026 | G11: =IF(OR(E11="",F11=""),"",MAX(0,DATEDIF(E11,F11,"D"))) -> 8 | H11: Cardiology | I11: DR-001 | J11: =IF(I11="","",IFERROR(_xlfn.XLOOKUP(I11,DR_Master!A:A,DR_Master!B:B),"Doctor ID not found")) -> Dr. Arjun Bose | K11: BED-001 | L11: =IF(K11="","",IFERROR(_xlfn.XLOOKUP(K11,BED_Master!A:A,BED_Master!B:B),"Bed ID not found")) -> General Ward | M11: Urinary Tract Infection | N11: N39.0 | O11: Discharged | P11: Self | Q11: Billing Clerk
A12: =IF(B12="","","ADM-"&TEXT(ROW(A8),"00000")) -> ADM-00008 | B12: PT-00008 | C12: =IF(B12="","",IFERROR(_xlfn.XLOOKUP(B12,PT_Master!A:A,PT_Master!C:C),"Patient ID not found")) -> Suresh Chatterjee | D12: OPD | E12: 10/09/2025 | F12: 10/09/2025 | G12: =IF(OR(E12="",F12=""),"",MAX(0,DATEDIF(E12,F12,"D"))) -> 0 | H12: Emergency | I12: DR-006 | J12: =IF(I12="","",IFERROR(_xlfn.XLOOKUP(I12,DR_Master!A:A,DR_Master!B:B),"Doctor ID not found")) -> Dr. Farhan Qureshi | L12: =IF(K12="","",IFERROR(_xlfn.XLOOKUP(K12,BED_Master!A:A,BED_Master!B:B),"Bed ID not found")) | M12: Febrile Seizure | N12: R56.0 | O12: Discharged | P12: GP Referral | Q12: Ward Nurse
A13: =IF(B13="","","ADM-"&TEXT(ROW(A9),"00000")) -> ADM-00009 | B13: PT-00009 | C13: =IF(B13="","",IFERROR(_xlfn.XLOOKUP(B13,PT_Master!A:A,PT_Master!C:C),"Patient ID not found")) -> Pooja Mukherjee | D13: OPD | E13: 25/11/2025 | F13: 25/11/2025 | G13: =IF(OR(E13="",F13=""),"",MAX(0,DATEDIF(E13,F13,"D"))) -> 0 | H13: Cardiology | I13: DR-009 | J13: =IF(I13="","",IFERROR(_xlfn.XLOOKUP(I13,DR_Master!A:A,DR_Master!B:B),"Doctor ID not found")) -> Dr. Kamala Nair | L13: =IF(K13="","",IFERROR(_xlfn.XLOOKUP(K13,BED_Master!A:A,BED_Master!B:B),"Bed ID not found")) | M13: Shoulder Dislocation | N13: S43.0 | O13: Discharged | P13: Emergency | Q13: Admin Manager
A14: =IF(B14="","","ADM-"&TEXT(ROW(A10),"00000")) -> ADM-00010 | B14: PT-00010 | C14: =IF(B14="","",IFERROR(_xlfn.XLOOKUP(B14,PT_Master!A:A,PT_Master!C:C),"Patient ID not found")) -> Arjun Bose | D14: OPD | E14: 14/02/2026 | F14: 14/02/2026 | G14: =IF(OR(E14="",F14=""),"",MAX(0,DATEDIF(E14,F14,"D"))) -> 0 | H14: Cardiology | I14: DR-001 | J14: =IF(I14="","",IFERROR(_xlfn.XLOOKUP(I14,DR_Master!A:A,DR_Master!B:B),"Doctor ID not found")) -> Dr. Arjun Bose | L14: =IF(K14="","",IFERROR(_xlfn.XLOOKUP(K14,BED_Master!A:A,BED_Master!B:B),"Bed ID not found")) | M14: Gestational Diabetes | N14: O24.4 | O14: Discharged | P14: Self | Q14: Billing Clerk
A15: =IF(B15="","","ADM-"&TEXT(ROW(A11),"00000")) -> ADM-00011 | B15: PT-00011 | C15: =IF(B15="","",IFERROR(_xlfn.XLOOKUP(B15,PT_Master!A:A,PT_Master!C:C),"Patient ID not found")) -> Meena Sen | D15: Emergency | E15: 11/10/2025 | F15: 12/10/2025 | G15: =IF(OR(E15="",F15=""),"",MAX(0,DATEDIF(E15,F15,"D"))) -> 1 | H15: Orthopaedics | I15: DR-010 | J15: =IF(I15="","",IFERROR(_xlfn.XLOOKUP(I15,DR_Master!A:A,DR_Master!B:B),"Doctor ID not found")) -> Dr. Subhash Patra | L15: =IF(K15="","",IFERROR(_xlfn.XLOOKUP(K15,BED_Master!A:A,BED_Master!B:B),"Bed ID not found")) | M15: Type 2 Diabetes Mellitus | N15: E11.9 | O15: Discharged | P15: Online Booking | Q15: Admin Manager
A16: =IF(B16="","","ADM-"&TEXT(ROW(A12),"00000")) -> ADM-00012 | B16: PT-00012 | C16: =IF(B16="","",IFERROR(_xlfn.XLOOKUP(B16,PT_Master!A:A,PT_Master!C:C),"Patient ID not found")) -> Vikram Ghosh | D16: IPD | E16: 14/08/2025 | F16: 17/08/2025 | G16: =IF(OR(E16="",F16=""),"",MAX(0,DATEDIF(E16,F16,"D"))) -> 3 | H16: Cardiology | I16: DR-001 | J16: =IF(I16="","",IFERROR(_xlfn.XLOOKUP(I16,DR_Master!A:A,DR_Master!B:B),"Doctor ID not found")) -> Dr. Arjun Bose | K16: BED-011 | L16: =IF(K16="","",IFERROR(_xlfn.XLOOKUP(K16,BED_Master!A:A,BED_Master!B:B),"Bed ID not found")) -> Semi-Private | M16: Asthma | N16: J45.9 | O16: Discharged | P16: Specialist Referral | Q16: Receptionist
A17: =IF(B17="","","ADM-"&TEXT(ROW(A13),"00000")) -> ADM-00013 | B17: PT-00013 | C17: =IF(B17="","",IFERROR(_xlfn.XLOOKUP(B17,PT_Master!A:A,PT_Master!C:C),"Patient ID not found")) -> Divya Banerjee | D17: IPD | E17: 13/02/2026 | F17: 16/02/2026 | G17: =IF(OR(E17="",F17=""),"",MAX(0,DATEDIF(E17,F17,"D"))) -> 3 | H17: General Medicine | I17: DR-008 | J17: =IF(I17="","",IFERROR(_xlfn.XLOOKUP(I17,DR_Master!A:A,DR_Master!B:B),"Doctor ID not found")) -> Dr. Prabal Roy | K17: BED-025 | L17: =IF(K17="","",IFERROR(_xlfn.XLOOKUP(K17,BED_Master!A:A,BED_Master!B:B),"Bed ID not found")) -> ICU | M17: Cholecystitis | N17: K81.0 | O17: Discharged | P17: Emergency | Q17: Billing Clerk
A18: =IF(B18="","","ADM-"&TEXT(ROW(A14),"00000")) -> ADM-00014 | B18: PT-00014 | C18: =IF(B18="","",IFERROR(_xlfn.XLOOKUP(B18,PT_Master!A:A,PT_Master!C:C),"Patient ID not found")) -> Rajan Dey | D18: OPD | E18: 01/11/2025 | F18: 01/11/2025 | G18: =IF(OR(E18="",F18=""),"",MAX(0,DATEDIF(E18,F18,"D"))) -> 0 | H18: Cardiology | I18: DR-009 | J18: =IF(I18="","",IFERROR(_xlfn.XLOOKUP(I18,DR_Master!A:A,DR_Master!B:B),"Doctor ID not found")) -> Dr. Kamala Nair | L18: =IF(K18="","",IFERROR(_xlfn.XLOOKUP(K18,BED_Master!A:A,BED_Master!B:B),"Bed ID not found")) | M18: Acute Gastroenteritis | N18: A09 | O18: Discharged | P18: Emergency | Q18: Ward Nurse
A19: =IF(B19="","","ADM-"&TEXT(ROW(A15),"00000")) -> ADM-00015 | B19: PT-00015 | C19: =IF(B19="","",IFERROR(_xlfn.XLOOKUP(B19,PT_Master!A:A,PT_Master!C:C),"Patient ID not found")) -> Sunita Pal | D19: OPD | E19: 07/04/2026 | F19: 07/04/2026 | G19: =IF(OR(E19="",F19=""),"",MAX(0,DATEDIF(E19,F19,"D"))) -> 0 | H19: General Medicine | I19: DR-003 | J19: =IF(I19="","",IFERROR(_xlfn.XLOOKUP(I19,DR_Master!A:A,DR_Master!B:B),"Doctor ID not found")) -> Dr. Sanjay Ghosh | L19: =IF(K19="","",IFERROR(_xlfn.XLOOKUP(K19,BED_Master!A:A,BED_Master!B:B),"Bed ID not found")) | M19: Unstable Angina | N19: I20.0 | O19: Discharged | P19: GP Referral | Q19: Ward Nurse
A20: =IF(B20="","","ADM-"&TEXT(ROW(A16),"00000")) -> ADM-00016 | B20: PT-00016 | C20: =IF(B20="","",IFERROR(_xlfn.XLOOKUP(B20,PT_Master!A:A,PT_Master!C:C),"Patient ID not found")) -> Ajay Nath | D20: OPD | E20: 21/04/2026 | F20: 21/04/2026 | G20: =IF(OR(E20="",F20=""),"",MAX(0,DATEDIF(E20,F20,"D"))) -> 0 | H20: Emergency | I20: DR-006 | J20: =IF(I20="","",IFERROR(_xlfn.XLOOKUP(I20,DR_Master!A:A,DR_Master!B:B),"Doctor ID not found")) -> Dr. Farhan Qureshi | L20: =IF(K20="","",IFERROR(_xlfn.XLOOKUP(K20,BED_Master!A:A,BED_Master!B:B),"Bed ID not found")) | M20: Hypertension | N20: I10 | O20: Discharged | P20: GP Referral | Q20: Ward Nurse
A21: =IF(B21="","","ADM-"&TEXT(ROW(A17),"00000")) -> ADM-00017 | B21: PT-00017 | C21: =IF(B21="","",IFERROR(_xlfn.XLOOKUP(B21,PT_Master!A:A,PT_Master!C:C),"Patient ID not found")) -> Nisha Saha | D21: OPD | E21: 06/08/2025 | F21: 06/08/2025 | G21: =IF(OR(E21="",F21=""),"",MAX(0,DATEDIF(E21,F21,"D"))) -> 0 | H21: Gynaecology | I21: DR-002 | J21: =IF(I21="","",IFERROR(_xlfn.XLOOKUP(I21,DR_Master!A:A,DR_Master!B:B),"Doctor ID not found")) -> Dr. Meena Pillai | L21: =IF(K21="","",IFERROR(_xlfn.XLOOKUP(K21,BED_Master!A:A,BED_Master!B:B),"Bed ID not found")) | M21: Neonatal Jaundice | N21: P59.9 | O21: Discharged | P21: Online Booking | Q21: Receptionist
A22: =IF(B22="","","ADM-"&TEXT(ROW(A18),"00000")) -> ADM-00018 | B22: PT-00018 | C22: =IF(B22="","",IFERROR(_xlfn.XLOOKUP(B22,PT_Master!A:A,PT_Master!C:C),"Patient ID not found")) -> Sanjay Biswas | D22: OPD | E22: 12/10/2025 | F22: 12/10/2025 | G22: =IF(OR(E22="",F22=""),"",MAX(0,DATEDIF(E22,F22,"D"))) -> 0 | H22: Orthopaedics | I22: DR-010 | J22: =IF(I22="","",IFERROR(_xlfn.XLOOKUP(I22,DR_Master!A:A,DR_Master!B:B),"Doctor ID not found")) -> Dr. Subhash Patra | L22: =IF(K22="","",IFERROR(_xlfn.XLOOKUP(K22,BED_Master!A:A,BED_Master!B:B),"Bed ID not found")) | M22: GERD | N22: K21.0 | O22: Discharged | P22: GP Referral | Q22: Ward Nurse
A23: =IF(B23="","","ADM-"&TEXT(ROW(A19),"00000")) -> ADM-00019 | B23: PT-00019 | C23: =IF(B23="","",IFERROR(_xlfn.XLOOKUP(B23,PT_Master!A:A,PT_Master!C:C),"Patient ID not found")) -> Rekha Chakraborty | D23: IPD | E23: 14/11/2025 | F23: 23/11/2025 | G23: =IF(OR(E23="",F23=""),"",MAX(0,DATEDIF(E23,F23,"D"))) -> 9 | H23: Orthopaedics | I23: DR-005 | J23: =IF(I23="","",IFERROR(_xlfn.XLOOKUP(I23,DR_Master!A:A,DR_Master!B:B),"Doctor ID not found")) -> Dr. Tanmoy Das | K23: BED-001 | L23: =IF(K23="","",IFERROR(_xlfn.XLOOKUP(K23,BED_Master!A:A,BED_Master!B:B),"Bed ID not found")) -> General Ward | M23: Cholecystitis | N23: K81.0 | O23: Active | P23: Specialist Referral | Q23: Receptionist
A24: =IF(B24="","","ADM-"&TEXT(ROW(A20),"00000")) -> ADM-00020 | B24: PT-00020 | C24: =IF(B24="","",IFERROR(_xlfn.XLOOKUP(B24,PT_Master!A:A,PT_Master!C:C),"Patient ID not found")) -> Manish Mitra | D24: OPD | E24: 16/04/2026 | F24: 16/04/2026 | G24: =IF(OR(E24="",F24=""),"",MAX(0,DATEDIF(E24,F24,"D"))) -> 0 | H24: Orthopaedics | I24: DR-005 | J24: =IF(I24="","",IFERROR(_xlfn.XLOOKUP(I24,DR_Master!A:A,DR_Master!B:B),"Doctor ID not found")) -> Dr. Tanmoy Das | L24: =IF(K24="","",IFERROR(_xlfn.XLOOKUP(K24,BED_Master!A:A,BED_Master!B:B),"Bed ID not found")) | M24: Type 2 Diabetes Mellitus | N24: E11.9 | O24: Discharged | P24: Emergency | Q24: Receptionist
A25: =IF(B25="","","ADM-"&TEXT(ROW(A21),"00000")) -> ADM-00021 | B25: PT-00021 | C25: =IF(B25="","",IFERROR(_xlfn.XLOOKUP(B25,PT_Master!A:A,PT_Master!C:C),"Patient ID not found")) -> Geeta Paul | D25: IPD | E25: 12/03/2026 | F25: 19/03/2026 | G25: =IF(OR(E25="",F25=""),"",MAX(0,DATEDIF(E25,F25,"D"))) -> 7 | H25: Gynaecology | I25: DR-002 | J25: =IF(I25="","",IFERROR(_xlfn.XLOOKUP(I25,DR_Master!A:A,DR_Master!B:B),"Doctor ID not found")) -> Dr. Meena Pillai | K25: BED-009 | L25: =IF(K25="","",IFERROR(_xlfn.XLOOKUP(K25,BED_Master!A:A,BED_Master!B:B),"Bed ID not found")) -> Semi-Private | M25: Hypertension | N25: I10 | O25: Discharged | P25: Specialist Referral | Q25: Billing Clerk
A26: =IF(B26="","","ADM-"&TEXT(ROW(A22),"00000")) -> ADM-00022 | B26: PT-00022 | C26: =IF(B26="","",IFERROR(_xlfn.XLOOKUP(B26,PT_Master!A:A,PT_Master!C:C),"Patient ID not found")) -> Arun Karmakar | D26: IPD | E26: 07/10/2025 | F26: 15/10/2025 | G26: =IF(OR(E26="",F26=""),"",MAX(0,DATEDIF(E26,F26,"D"))) -> 8 | H26: Diagnostics | I26: DR-007 | J26: =IF(I26="","",IFERROR(_xlfn.XLOOKUP(I26,DR_Master!A:A,DR_Master!B:B),"Doctor ID not found")) -> Dr. Lipika Sen | K26: BED-011 | L26: =IF(K26="","",IFERROR(_xlfn.XLOOKUP(K26,BED_Master!A:A,BED_Master!B:B),"Bed ID not found")) -> Semi-Private | M26: COPD Exacerbation | N26: J44.1 | O26: Transferred | P26: Emergency | Q26: Receptionist
A27: =IF(B27="","","ADM-"&TEXT(ROW(A23),"00000")) -> ADM-00023 | B27: PT-00023 | C27: =IF(B27="","",IFERROR(_xlfn.XLOOKUP(B27,PT_Master!A:A,PT_Master!C:C),"Patient ID not found")) -> Lata Mandal | D27: OPD | E27: 05/04/2026 | F27: 05/04/2026 | G27: =IF(OR(E27="",F27=""),"",MAX(0,DATEDIF(E27,F27,"D"))) -> 0 | H27: Paediatrics | I27: DR-004 | J27: =IF(I27="","",IFERROR(_xlfn.XLOOKUP(I27,DR_Master!A:A,DR_Master!B:B),"Doctor ID not found")) -> Dr. Ritika Sharma | L27: =IF(K27="","",IFERROR(_xlfn.XLOOKUP(K27,BED_Master!A:A,BED_Master!B:B),"Bed ID not found")) | M27: Pancreatitis | N27: K85.9 | O27: Discharged | P27: Online Booking | Q27: Admin Manager
A28: =IF(B28="","","ADM-"&TEXT(ROW(A24),"00000")) -> ADM-00024 | B28: PT-00024 | C28: =IF(B28="","",IFERROR(_xlfn.XLOOKUP(B28,PT_Master!A:A,PT_Master!C:C),"Patient ID not found")) -> Deepak Sarkar | D28: IPD | E28: 13/11/2025 | F28: 21/11/2025 | G28: =IF(OR(E28="",F28=""),"",MAX(0,DATEDIF(E28,F28,"D"))) -> 8 | H28: Orthopaedics | I28: DR-005 | J28: =IF(I28="","",IFERROR(_xlfn.XLOOKUP(I28,DR_Master!A:A,DR_Master!B:B),"Doctor ID not found")) -> Dr. Tanmoy Das | K28: BED-013 | L28: =IF(K28="","",IFERROR(_xlfn.XLOOKUP(K28,BED_Master!A:A,BED_Master!B:B),"Bed ID not found")) -> Semi-Private | M28: Fracture Femur | N28: S72.0 | O28: Discharged | P28: Emergency | Q28: Ward Nurse
A29: =IF(B29="","","ADM-"&TEXT(ROW(A25),"00000")) -> ADM-00025 | B29: PT-00025 | C29: =IF(B29="","",IFERROR(_xlfn.XLOOKUP(B29,PT_Master!A:A,PT_Master!C:C),"Patient ID not found")) -> Shilpa Patra | D29: OPD | E29: 16/08/2025 | F29: 16/08/2025 | G29: =IF(OR(E29="",F29=""),"",MAX(0,DATEDIF(E29,F29,"D"))) -> 0 | H29: Orthopaedics | I29: DR-005 | J29: =IF(I29="","",IFERROR(_xlfn.XLOOKUP(I29,DR_Master!A:A,DR_Master!B:B),"Doctor ID not found")) -> Dr. Tanmoy Das | L29: =IF(K29="","",IFERROR(_xlfn.XLOOKUP(K29,BED_Master!A:A,BED_Master!B:B),"Bed ID not found")) | M29: Coronary Artery Disease | N29: I25.1 | O29: Discharged | P29: Online Booking | Q29: Admin Manager
A30: =IF(B30="","","ADM-"&TEXT(ROW(A26),"00000")) -> ADM-00026 | B30: PT-00026 | C30: =IF(B30="","",IFERROR(_xlfn.XLOOKUP(B30,PT_Master!A:A,PT_Master!C:C),"Patient ID not found")) -> Rajesh Haldar | D30: IPD | E30: 21/03/2026 | F30: 31/03/2026 | G30: =IF(OR(E30="",F30=""),"",MAX(0,DATEDIF(E30,F30,"D"))) -> 10 | H30: Cardiology | I30: DR-001 | J30: =IF(I30="","",IFERROR(_xlfn.XLOOKUP(I30,DR_Master!A:A,DR_Master!B:B),"Doctor ID not found")) -> Dr. Arjun Bose | K30: BED-024 | L30: =IF(K30="","",IFERROR(_xlfn.XLOOKUP(K30,BED_Master!A:A,BED_Master!B:B),"Bed ID not found")) -> ICU | M30: Acute Myocardial Infarction | N30: I21.9 | O30: Discharged | P30: Another Hospital | Q30: Ward Nurse
A31: =IF(B31="","","ADM-"&TEXT(ROW(A27),"00000")) -> ADM-00027 | B31: PT-00027 | C31: =IF(B31="","",IFERROR(_xlfn.XLOOKUP(B31,PT_Master!A:A,PT_Master!C:C),"Patient ID not found")) -> Asha Majumdar | D31: OPD | E31: 15/08/2025 | F31: 15/08/2025 | G31: =IF(OR(E31="",F31=""),"",MAX(0,DATEDIF(E31,F31,"D"))) -> 0 | H31: Gynaecology | I31: DR-002 | J31: =IF(I31="","",IFERROR(_xlfn.XLOOKUP(I31,DR_Master!A:A,DR_Master!B:B),"Doctor ID not found")) -> Dr. Meena Pillai | L31: =IF(K31="","",IFERROR(_xlfn.XLOOKUP(K31,BED_Master!A:A,BED_Master!B:B),"Bed ID not found")) | M31: Cellulitis | N31: L03.9 | O31: Discharged | P31: Specialist Referral | Q31: Billing Clerk
A32: =IF(B32="","","ADM-"&TEXT(ROW(A28),"00000")) -> ADM-00028 | B32: PT-00028 | C32: =IF(B32="","",IFERROR(_xlfn.XLOOKUP(B32,PT_Master!A:A,PT_Master!C:C),"Patient ID not found")) -> Vivek Bhattacharya | D32: OPD | E32: 26/02/2026 | F32: 26/02/2026 | G32: =IF(OR(E32="",F32=""),"",MAX(0,DATEDIF(E32,F32,"D"))) -> 0 | H32: Paediatrics | I32: DR-004 | J32: =IF(I32="","",IFERROR(_xlfn.XLOOKUP(I32,DR_Master!A:A,DR_Master!B:B),"Doctor ID not found")) -> Dr. Ritika Sharma | L32: =IF(K32="","",IFERROR(_xlfn.XLOOKUP(K32,BED_Master!A:A,BED_Master!B:B),"Bed ID not found")) | M32: Ischaemic Stroke | N32: I63.9 | O32: Discharged | P32: Emergency | Q32: Ward Nurse
A33: =IF(B33="","","ADM-"&TEXT(ROW(A29),"00000")) -> ADM-00029 | B33: PT-00029 | C33: =IF(B33="","",IFERROR(_xlfn.XLOOKUP(B33,PT_Master!A:A,PT_Master!C:C),"Patient ID not found")) -> Smita Chowdhury | D33: OPD | E33: 29/07/2025 | F33: 29/07/2025 | G33: =IF(OR(E33="",F33=""),"",MAX(0,DATEDIF(E33,F33,"D"))) -> 0 | H33: Cardiology | I33: DR-009 | J33: =IF(I33="","",IFERROR(_xlfn.XLOOKUP(I33,DR_Master!A:A,DR_Master!B:B),"Doctor ID not found")) -> Dr. Kamala Nair | L33: =IF(K33="","",IFERROR(_xlfn.XLOOKUP(K33,BED_Master!A:A,BED_Master!B:B),"Bed ID not found")) | M33: Viral Fever | N33: A99 | O33: Discharged | P33: Online Booking | Q33: Ward Nurse
A34: =IF(B34="","","ADM-"&TEXT(ROW(A30),"00000")) -> ADM-00030 | B34: PT-00030 | C34: =IF(B34="","",IFERROR(_xlfn.XLOOKUP(B34,PT_Master!A:A,PT_Master!C:C),"Patient ID not found")) -> Prakash Lahiri | D34: OPD | E34: 04/08/2025 | F34: 04/08/2025 | G34: =IF(OR(E34="",F34=""),"",MAX(0,DATEDIF(E34,F34,"D"))) -> 0 | H34: Orthopaedics | I34: DR-005 | J34: =IF(I34="","",IFERROR(_xlfn.XLOOKUP(I34,DR_Master!A:A,DR_Master!B:B),"Doctor ID not found")) -> Dr. Tanmoy Das | L34: =IF(K34="","",IFERROR(_xlfn.XLOOKUP(K34,BED_Master!A:A,BED_Master!B:B),"Bed ID not found")) | M34: Lumbar Disc Herniation | N34: M51.1 | O34: Discharged | P34: Corporate Tie-up | Q34: Receptionist
A35: =IF(B35="","","ADM-"&TEXT(ROW(A31),"00000")) -> ADM-00031 | B35: PT-00031 | C35: =IF(B35="","",IFERROR(_xlfn.XLOOKUP(B35,PT_Master!A:A,PT_Master!C:C),"Patient ID not found")) -> Usha Ganguly | D35: OPD | E35: 02/09/2025 | F35: 02/09/2025 | G35: =IF(OR(E35="",F35=""),"",MAX(0,DATEDIF(E35,F35,"D"))) -> 0 | H35: Paediatrics | I35: DR-004 | J35: =IF(I35="","",IFERROR(_xlfn.XLOOKUP(I35,DR_Master!A:A,DR_Master!B:B),"Doctor ID not found")) -> Dr. Ritika Sharma | L35: =IF(K35="","",IFERROR(_xlfn.XLOOKUP(K35,BED_Master!A:A,BED_Master!B:B),"Bed ID not found")) | M35: Septicaemia | N35: A41.9 | O35: Discharged | P35: Self | Q35: Ward Nurse
A36: =IF(B36="","","ADM-"&TEXT(ROW(A32),"00000")) -> ADM-00032 | B36: PT-00032 | C36: =IF(B36="","",IFERROR(_xlfn.XLOOKUP(B36,PT_Master!A:A,PT_Master!C:C),"Patient ID not found")) -> Nikhil Dutta | D36: OPD | E36: 13/11/2025 | F36: 13/11/2025 | G36: =IF(OR(E36="",F36=""),"",MAX(0,DATEDIF(E36,F36,"D"))) -> 0 | H36: Cardiology | I36: DR-001 | J36: =IF(I36="","",IFERROR(_xlfn.XLOOKUP(I36,DR_Master!A:A,DR_Master!B:B),"Doctor ID not found")) -> Dr. Arjun Bose | L36: =IF(K36="","",IFERROR(_xlfn.XLOOKUP(K36,BED_Master!A:A,BED_Master!B:B),"Bed ID not found")) | M36: Acute Myocardial Infarction | N36: I21.9 | O36: Discharged | P36: Another Hospital | Q36: Receptionist
A37: =IF(B37="","","ADM-"&TEXT(ROW(A33),"00000")) -> ADM-00033 | B37: PT-00033 | C37: =IF(B37="","",IFERROR(_xlfn.XLOOKUP(B37,PT_Master!A:A,PT_Master!C:C),"Patient ID not found")) -> Anjali Sanyal | D37: OPD | E37: 10/12/2025 | F37: 10/12/2025 | G37: =IF(OR(E37="",F37=""),"",MAX(0,DATEDIF(E37,F37,"D"))) -> 0 | H37: Paediatrics | I37: DR-004 | J37: =IF(I37="","",IFERROR(_xlfn.XLOOKUP(I37,DR_Master!A:A,DR_Master!B:B),"Doctor ID not found")) -> Dr. Ritika Sharma | L37: =IF(K37="","",IFERROR(_xlfn.XLOOKUP(K37,BED_Master!A:A,BED_Master!B:B),"Bed ID not found")) | M37: Dengue Fever | N37: A97.0 | O37: Discharged | P37: Online Booking | Q37: Admin Manager
A38: =IF(B38="","","ADM-"&TEXT(ROW(A34),"00000")) -> ADM-00034 | B38: PT-00034 | C38: =IF(B38="","",IFERROR(_xlfn.XLOOKUP(B38,PT_Master!A:A,PT_Master!C:C),"Patient ID not found")) -> Sunil Bhatt | D38: OPD | E38: 08/12/2025 | F38: 08/12/2025 | G38: =IF(OR(E38="",F38=""),"",MAX(0,DATEDIF(E38,F38,"D"))) -> 0 | H38: Emergency | I38: DR-006 | J38: =IF(I38="","",IFERROR(_xlfn.XLOOKUP(I38,DR_Master!A:A,DR_Master!B:B),"Doctor ID not found")) -> Dr. Farhan Qureshi | L38: =IF(K38="","",IFERROR(_xlfn.XLOOKUP(K38,BED_Master!A:A,BED_Master!B:B),"Bed ID not found")) | M38: Paediatric Bronchitis | N38: J20.9 | O38: Discharged | P38: Another Hospital | Q38: Admin Manager
A39: =IF(B39="","","ADM-"&TEXT(ROW(A35),"00000")) -> ADM-00035 | B39: PT-00035 | C39: =IF(B39="","",IFERROR(_xlfn.XLOOKUP(B39,PT_Master!A:A,PT_Master!C:C),"Patient ID not found")) -> Poonam Joshi | D39: IPD | E39: 05/05/2026 | F39: 16/05/2026 | G39: =IF(OR(E39="",F39=""),"",MAX(0,DATEDIF(E39,F39,"D"))) -> 11 | H39: Cardiology | I39: DR-001 | J39: =IF(I39="","",IFERROR(_xlfn.XLOOKUP(I39,DR_Master!A:A,DR_Master!B:B),"Doctor ID not found")) -> Dr. Arjun Bose | K39: BED-015 | L39: =IF(K39="","",IFERROR(_xlfn.XLOOKUP(K39,BED_Master!A:A,BED_Master!B:B),"Bed ID not found")) -> Semi-Private | M39: Deep Vein Thrombosis | N39: I82.4 | O39: Active | P39: GP Referral | Q39: Billing Clerk
A40: =IF(B40="","","ADM-"&TEXT(ROW(A36),"00000")) -> ADM-00036 | B40: PT-00036 | C40: =IF(B40="","",IFERROR(_xlfn.XLOOKUP(B40,PT_Master!A:A,PT_Master!C:C),"Patient ID not found")) -> Hemant Patel | D40: IPD | E40: 27/11/2025 | F40: 30/11/2025 | G40: =IF(OR(E40="",F40=""),"",MAX(0,DATEDIF(E40,F40,"D"))) -> 3 | H40: Diagnostics | I40: DR-007 | J40: =IF(I40="","",IFERROR(_xlfn.XLOOKUP(I40,DR_Master!A:A,DR_Master!B:B),"Doctor ID not found")) -> Dr. Lipika Sen | K40: BED-023 | L40: =IF(K40="","",IFERROR(_xlfn.XLOOKUP(K40,BED_Master!A:A,BED_Master!B:B),"Bed ID not found")) -> ICU | M40: Unstable Angina | N40: I20.0 | O40: Discharged | P40: GP Referral | Q40: Ward Nurse
